<?xml version="1.0" encoding="utf-8"?>
<!-- This URDF was automatically created by SolidWorks to URDF Exporter! Originally created by Stephen Brawner (brawner@gmail.com) 
     Commit Version: 1.6.0-4-g7f85cfe  Build Version: 1.6.7995.38578
     For more information, please see http://wiki.ros.org/sw_urdf_exporter -->
<robot
  name="RobotBimanualV4">
  <link name="base_link_mobile">
    <inertial>
      <mass value="0.0"/>
      <origin rpy="0 0 0" xyz="0 0 0"/>
      <inertia ixx="0.0" ixy="0.0" ixz="0.0" iyy="0.0" iyz="0.0" izz="0.0"/>
    </inertial>
  </link>
  <joint name="base_link-base_link_inertia" type="fixed">
    <parent link="base_link_mobile"/>
    <child link="base_link"/>
    <origin rpy="0 0 0" xyz="0 0 0"/>
  </joint>
  <link
    name="base_link">
    <inertial>
      <origin
        xyz="0.00507379776771603 0.000344479206440096 0.493021917987909"
        rpy="0 0 0" />
      <mass
        value="6.48543411303863" />
      <inertia
        ixx="0.337312998632581"
        ixy="-7.79460815808494E-06"
        ixz="-0.00341337207209014"
        iyy="0.336184764674995"
        iyz="2.35532268575879E-05"
        izz="0.00769415237418266" />
    </inertial>
    <visual>
      <origin
        xyz="0 0 0"
        rpy="0 0 0" />
      <geometry>
        <!-- <mesh
          filename="package://RobotBimanualV4//visual/base_link.obj" /> -->
        <mesh
          filename="package://RobotBimanualV4//visual/base_mobile.obj" />
      </geometry>
      <material
        name="">
        <color
          rgba="0.792156862745098 0.819607843137255 0.933333333333333 1" />
      </material>
    </visual>
    <collision>
      <origin
        xyz="0 0 0"
        rpy="0 0 0" />
      <geometry>
        <!-- <mesh
          filename="package://RobotBimanualV4//collision/base_link.obj" /> -->
        <mesh
          filename="package://RobotBimanualV4//collision/cvx_base_mobile.obj" />
      </geometry>
    </collision>
  </link>
  <link
    name="link7">
    <inertial>
      <origin
        xyz="0.00239406 -0.00016204 0.05155291"
        rpy="0 0 0" />
      <mass
        value="0.706" />
      <inertia
        ixx="0.00074592"
        ixy="-2.03E-06"
        ixz="-1.52E-06"
        iyy="0.00053798"
        iyz="-3.35E-06"
        izz="0.00050821" />
    </inertial>
    <visual>
      <origin
        xyz="0 0 0"
        rpy="0 0 0" />
      <geometry>
        <mesh
          filename="package://RobotBimanualV4//visual/link7.obj" />
      </geometry>
      <material
        name="">
        <color
          rgba="0.79216 0.81961 0.93333 1" />
      </material>
    </visual>
    <collision>
      <origin
        xyz="0 0 0"
        rpy="0 0 0" />
      <geometry>
        <mesh
          filename="package://RobotBimanualV4//collision/cvx_link7.obj" />
      </geometry>
    </collision>
  </link>
  <joint
    name="joint7"
    type="revolute">
    <origin
      xyz="0.02 -0.1036 0.8358"
      rpy="0 0 0" />
    <parent
      link="base_link" />
    <child
      link="link7" />
    <axis
      xyz="0 0 1" />
    <limit
      lower="-3"
      upper="3"
      effort="4"
      velocity="10.00" />  
  </joint>
  <link
    name="link8">
    <inertial>
      <origin
        xyz="-0.00124394 7.606E-05 0.05454155"
        rpy="0 0 0" />
      <mass
        value="0.659" />
      <inertia
        ixx="0.00064811"
        ixy="-1.1E-06"
        ixz="-7.3E-07"
        iyy="0.0004522"
        iyz="1.03E-06"
        izz="0.00043369" />
    </inertial>
    <visual>
      <origin
        xyz="0 0 0"
        rpy="0 0 0" />
      <geometry>
        <mesh
          filename="package://RobotBimanualV4//visual/link8.obj" />
      </geometry>
      <material
        name="">
        <color
          rgba="0.79216 0.81961 0.93333 1" />
      </material>
    </visual>
    <collision>
      <origin
        xyz="0 0 0"
        rpy="0 0 0" />
      <geometry>
        <mesh
          filename="package://RobotBimanualV4//collision/cvx_link8.obj" />
      </geometry>
    </collision>
  </link>
  <joint
    name="joint8"
    type="revolute">
    <origin
      xyz="-0.02205 0 0.0528"
      rpy="1.5708 0 -1.5708" />
    <parent
      link="link7" />
    <child
      link="link8" />
    <axis
      xyz="0 0 1" />
    <limit
      lower="-3"
      upper="3"
      effort="4"
      velocity="10.00" />
  </joint>
  <link
    name="link9">
    <inertial>
      <origin
        xyz="-0.03505563 0.00468094 0.05453087"
        rpy="0 0 0" />
      <mass
        value="1.095" />
      <inertia
        ixx="0.00161845"
        ixy="-0.00039365"
        ixz="-0.00105521"
        iyy="0.00662637"
        iyz="0.00018923"
        izz="0.00652496" />
    </inertial>
    <visual>
      <origin
        xyz="0 0 0"
        rpy="0 0 0" />
      <geometry>
        <mesh
          filename="package://RobotBimanualV4//visual/link9.obj" />
      </geometry>
      <material
        name="">
        <color
          rgba="0.79216 0.81961 0.93333 1" />
      </material>
    </visual>
    <collision>
      <origin
        xyz="0 0 0"
        rpy="0 0 0" />
      <geometry>
        <mesh
          filename="package://RobotBimanualV4//collision/cvx_link9.obj" />
      </geometry>
    </collision>
  </link>
  <joint
    name="joint9"
    type="revolute">
    <origin
      xyz="0.023 0 0.0565"
      rpy="1.5708 0 1.5708" />
    <parent
      link="link8" />
    <child
      link="link9" />
    <axis
      xyz="0 0 1" />
    <limit
      lower="-3"
      upper="3.14159265"
      effort="4"
      velocity="10.00" />
  </joint>
  <link
    name="link10">
    <inertial>
      <origin
        xyz="-0.00914828 -0.00042727 7.13E-06"
        rpy="0 0 0" />
      <mass
        value="0.268" />
      <inertia
        ixx="9.136E-05"
        ixy="7E-08"
        ixz="2E-08"
        iyy="0.00013894"
        iyz="0"
        izz="0.00013031" />
    </inertial>
    <visual>
      <origin
        xyz="0 0 0"
        rpy="0 0 0" />
      <geometry>
        <mesh
          filename="package://RobotBimanualV4//visual/link10.obj" />
      </geometry>
      <material
        name="">
        <color
          rgba="0.79216 0.81961 0.93333 1" />
      </material>
    </visual>
    <collision>
      <origin
        xyz="0 0 0"
        rpy="0 0 0" />
      <geometry>
        <mesh
          filename="package://RobotBimanualV4//collision/cvx_link10.obj" />
      </geometry>
    </collision>
  </link>
  <joint
    name="joint10"
    type="revolute">
    <origin
      xyz="-0.25 0 0.08318"
      rpy="-3.1416 0 -1.5708" />
    <parent
      link="link9" />
    <child
      link="link10" />
    <axis
      xyz="0 0 1" />
    <limit
      lower="-3"
      upper="3"
      effort="4"
      velocity="10.00" />
  </joint>
  <link
    name="link11">
    <inertial>
      <origin
        xyz="-0.00143459 -5.019E-05 0.22261684"
        rpy="0 0 0" />
      <mass
        value="0.285" />
      <inertia
        ixx="0.00170458"
        ixy="1.5E-07"
        ixz="-2.111E-05"
        iyy="0.00168732"
        iyz="-5.6E-07"
        izz="7.029E-05" />
    </inertial>
    <visual>
      <origin
        xyz="0 0 0"
        rpy="0 0 0" />
      <geometry>
        <mesh
          filename="package://RobotBimanualV4//visual/link11.obj" />
      </geometry>
      <material
        name="">
        <color
          rgba="0.79216 0.81961 0.93333 1" />
      </material>
    </visual>
    <collision>
      <origin
        xyz="0 0 0"
        rpy="0 0 0" />
      <geometry>
        <mesh
          filename="package://RobotBimanualV4//collision/cvx_link11.obj" />
      </geometry>
    </collision>
  </link>
  <joint
    name="joint11"
    type="revolute">
    <origin
      xyz="0.014 0.00010349 0"
      rpy="-1.5708 0 -1.5708" />
    <parent
      link="link10" />
    <child
      link="link11" />
    <axis
      xyz="0 0 1" />
    <limit
      lower="-3.66519143"
      upper="3"
      effort="1"
      velocity="15.00" />
  </joint>


  
  <link
    name="link11-1">
    <inertial>
      <origin
        xyz="0 0 0"
        rpy="0 0 0" />
      <mass
        value="0.01" />
      <inertia
        ixx="0.00017786"
        ixy="1.81E-06"
        ixz="5.4E-07"
        iyy="0.00025338"
        iyz="-3.72E-06"
        izz="0.00030962" />
    </inertial>
    <visual>
      <origin
        xyz="0 0 0"
        rpy="0 0 0" />
      <geometry>
        <!-- <mesh filename="package://RobotBimanualV4//visual/link12.obj" scale="0.001 0.001 0.001"/> -->
        <mesh filename="package://RobotBimanualV4//gripper_urdf/meshes/base_link.STL" scale="0.5 0.5 0.5"/>
      </geometry>
      <material
        name="">
        <color
          rgba="0.79216 0.81961 0.93333 1" />
      </material>
    </visual>
    <collision>
      <origin
        xyz="0 0 0"
        rpy="0 0 0" />
      <geometry>
        <!-- <mesh filename="package://RobotBimanualV4//collision/cvx_link12.obj" scale="0.001 0.001 0.001"/> -->
        <!-- <mesh filename="package://RobotBimanualV4//collision/cvx_link12.obj" scale="0.001 0.001 0.001"/> -->
        <mesh filename="package://RobotBimanualV4//gripper_urdf/meshes/base_link.STL" scale="0.5 0.5 0.5"/>
      </geometry>
    </collision>
  </link>
  <joint
      name="joint11-1"
      type="revolute">
      <origin
        xyz="0.012203 0 0.2634"
        rpy="1.5708 0 1.5708" />
      <parent
        link="link11" />
      <child
        link="link11-1" />
      <axis
        xyz="1 0 0" />
      <limit
        lower="-3"
        upper="3"
        effort="1"
        velocity="15.0" />
    </joint>



  <link
    name="link12">
    <inertial>
      <origin
        xyz="0.0001185 0.04488721 -0.01444679"
        rpy="0 0 0" />
      <mass
        value="0.23067563" />
      <inertia
        ixx="0.00017786"
        ixy="1.81E-06"
        ixz="5.4E-07"
        iyy="0.00025338"
        iyz="-3.72E-06"
        izz="0.00030962" />
    </inertial>
    <visual>
      <origin
        xyz="0 0 0"
        rpy="0 0 0" />
      <geometry>
        <!-- <mesh filename="package://RobotBimanualV4//visual/link12.obj" /> -->
        <!-- <mesh filename="package://RobotBimanualV4//visual/gripper_open20.obj" /> -->
        <mesh filename="package://RobotBimanualV4//visual/gripper_open40.obj" />
      </geometry>
      <material
        name="">
        <color
          rgba="0.79216 0.81961 0.93333 1" />
      </material>
    </visual>
    <collision>
      <origin
        xyz="0 0 0"
        rpy="0 0 0" />
      <geometry>
        <!-- <mesh filename="package://RobotBimanualV4//collision/cvx_link12.obj" /> -->
        <!-- <mesh filename="package://RobotBimanualV4//collision/cvx_gripper_open20.obj" /> -->
        <mesh filename="package://RobotBimanualV4//collision/cvx_gripper_open40.obj" />
      </geometry>
    </collision>
  </link>
  <joint
    name="joint12"
    type="revolute">
    <origin
      xyz="0 0 0 "
      rpy="0 0 0" />
    <parent
      link="link11-1" />
    <child
      link="link12" />
    <axis
      xyz="0 0 1" />
    <limit
      lower="-3"
      upper="3"
      effort="1"
      velocity="15.00" />
  </joint>
</robot>