<?xml version="1.0" encoding="utf-8"?>
<!-- This URDF was automatically created by SolidWorks to URDF Exporter! Originally created by Stephen Brawner (brawner@gmail.com) 
     Commit Version: 1.6.0-4-g7f85cfe  Build Version: 1.6.7995.38578
     For more information, please see http://wiki.ros.org/sw_urdf_exporter -->
<robot
  name="RobotBimanualV4">
  <link name="base_link_mobile">
    <inertial>
      <mass value="0.0"/>
      <origin rpy="0 0 0" xyz="0 0 0"/>
      <inertia ixx="0.0" ixy="0.0" ixz="0.0" iyy="0.0" iyz="0.0" izz="0.0"/>
    </inertial>
  </link>
  <joint name="base_link-base_link_inertia" type="fixed">
    <parent link="base_link_mobile"/>
    <child link="base_link"/>
    <origin rpy="0 0 0" xyz="0 0 0"/>
  </joint>
  <link
    name="base_link">
    <inertial>
      <origin
        xyz="0.00507379776771603 0.000344479206440096 0.493021917987909"
        rpy="0 0 0" />
      <mass
        value="6.48543411303863" />
      <inertia
        ixx="0.337312998632581"
        ixy="-7.79460815808494E-06"
        ixz="-0.00341337207209014"
        iyy="0.336184764674995"
        iyz="2.35532268575879E-05"
        izz="0.00769415237418266" />
    </inertial>
    <visual>
      <origin
        xyz="0 0 0"
        rpy="0 0 0" />
      <geometry>
        <!-- <mesh
          filename="package://RobotBimanualV4//visual/base_link.obj" /> -->
        <mesh
          filename="package://RobotBimanualV4//visual/base_mobile.obj" />
      </geometry>
      <material
        name="">
        <color
          rgba="0.792156862745098 0.819607843137255 0.933333333333333 1" />
      </material>
    </visual>
    <collision>
      <origin
        xyz="0 0 0"
        rpy="0 0 0" />
      <geometry>
        <!-- <mesh
          filename="package://RobotBimanualV4//collision/cvx_base_link.obj" /> -->
        <mesh
          filename="package://RobotBimanualV4//cvx/0_coacd/base_mobile.obj" />
      </geometry>
    </collision>
  </link>
  <link
    name="link1">
    <inertial>
      <origin
        xyz="0.00277367 6.161E-05 0.05165334"
        rpy="0 0 0" />
      <mass
        value="0.706" />
      <inertia
        ixx="0.00074611"
        ixy="5.4E-07"
        ixz="5.3E-07"
        iyy="0.00054009"
        iyz="3.26E-06"
        izz="0.00050643" />
    </inertial>
    <visual>
      <origin
        xyz="0 0 0"
        rpy="0 0 0" />
      <geometry>
        <mesh
          filename="package://RobotBimanualV4//visual/link1.obj" />
      </geometry>
      <material
        name="">
        <color
          rgba="0.79216 0.81961 0.93333 1" />
      </material>
    </visual>
    <collision>
      <origin
        xyz="0 0 0"
        rpy="0 0 0" />
      <geometry>
        <mesh
          filename="package://RobotBimanualV4//collision/cvx_link1.obj" />
      </geometry>
    </collision>
  </link>
  <joint
    name="joint1"
    type="revolute">
    <origin
      xyz="0.02 0.1036 0.8358"
      rpy="0 0 0" />
    <parent
      link="base_link" />
    <child
      link="link1" />
    <axis
      xyz="0 0 1" />
    <limit
      lower="-1.57079633"
      upper="0.87266463"
      effort="4"
      velocity="10.0" />
  </joint>
  <link
    name="link2">
    <inertial>
      <origin
        xyz="-0.00124394 -5.732E-05 0.0545228"
        rpy="0 0 0" />
      <mass
        value="0.659" />
      <inertia
        ixx="0.00064807"
        ixy="8.3E-07"
        ixz="-4.6E-07"
        iyy="0.00045162"
        iyz="-1.01E-06"
        izz="0.00043422" />
    </inertial>
    <visual>
      <origin
        xyz="0 0 0"
        rpy="0 0 0" />
      <geometry>
        <mesh
          filename="package://RobotBimanualV4//visual/link2.obj" />
      </geometry>
      <material
        name="">
        <color
          rgba="0.79216 0.81961 0.93333 1" />
      </material>
    </visual>
    <collision>
      <origin
        xyz="0 0 0"
        rpy="0 0 0" />
      <geometry>
        <mesh
          filename="package://RobotBimanualV4//collision/cvx_link2.obj" />
      </geometry>
    </collision>
  </link>
  <joint
    name="joint2"
    type="revolute">
    <origin
      xyz="-0.02205 0 0.0528"
      rpy="-1.5708 0 1.5708" />
    <parent
      link="link1" />
    <child
      link="link2" />
    <axis
      xyz="0 0 1" />
    <limit
      lower="-1.57079633"
      upper="1.3962634"
      effort="4"
      velocity="10.0" />
  </joint>
  <link
    name="link3">
    <inertial>
      <origin
        xyz="-0.03505493 -0.006151 0.05438578"
        rpy="0 0 0" />
      <mass
        value="1.095" />
      <inertia
        ixx="0.00161847"
        ixy="0.00042205"
        ixz="-0.00104433"
        iyy="0.0066165"
        iyz="-0.0001917"
        izz="0.00653551" />
    </inertial>
    <visual>
      <origin
        xyz="0 0 0"
        rpy="0 0 0" />
      <geometry>
        <mesh
          filename="package://RobotBimanualV4//visual/link3.obj" />
      </geometry>
      <material
        name="">
        <color
          rgba="0.79216 0.81961 0.93333 1" />
      </material>
    </visual>
    <collision>
      <origin
        xyz="0 0 0"
        rpy="0 0 0" />
      <geometry>
        <mesh
          filename="package://RobotBimanualV4//collision/cvx_link3.obj" />
      </geometry>
    </collision>
  </link>
  <joint
    name="joint3"
    type="revolute">
    <origin
      xyz="0.023 0 0.0565"
      rpy="-1.5708 0 -1.5708" />
    <parent
      link="link2" />
    <child
      link="link3" />
    <axis
      xyz="0 0 1" />
    <limit
      lower="-3.14159265"
      upper="1.3962634"
      effort="4"
      velocity="10.0" />
  </joint>
  <link
    name="link4">
    <inertial>
      <origin
        xyz="-0.00914828 -0.00042727 -7.12E-06"
        rpy="0 0 0" />
      <mass
        value="0.268" />
      <inertia
        ixx="9.136E-05"
        ixy="7E-08"
        ixz="-2E-08"
        iyy="0.00013894"
        iyz="0"
        izz="0.00013031" />
    </inertial>
    <visual>
      <origin
        xyz="0 0 0"
        rpy="0 0 0" />
      <geometry>
        <mesh
          filename="package://RobotBimanualV4//visual/link4.obj" />
      </geometry>
      <material
        name="">
        <color
          rgba="0.79216 0.81961 0.93333 1" />
      </material>
    </visual>
    <collision>
      <origin
        xyz="0 0 0"
        rpy="0 0 0" />
      <geometry>
        <mesh
          filename="package://RobotBimanualV4//collision/cvx_link4.obj" />
      </geometry>
    </collision>
  </link>
  <joint
    name="joint4"
    type="revolute">
    <origin
      xyz="-0.25 0 0.08318"
      rpy="0 0 1.5708" />
    <parent
      link="link3" />
    <child
      link="link4" />
    <axis
      xyz="0 0 1" />
    <limit
      lower="-0.78539816"
      upper="1.30899694"
      effort="4"
      velocity="10.0" />
  </joint>
  <link
    name="link5">
    <inertial>
      <origin
        xyz="-0.00143459 -5.019E-05 0.22261684"
        rpy="0 0 0" />
      <mass
        value="0.285" />
      <inertia
        ixx="0.00170458"
        ixy="1.5E-07"
        ixz="-2.111E-05"
        iyy="0.00168732"
        iyz="-5.6E-07"
        izz="7.029E-05" />
    </inertial>
    <visual>
      <origin
        xyz="0 0 0"
        rpy="0 0 0" />
      <geometry>
        <mesh
          filename="package://RobotBimanualV4//visual/link5.obj" />
      </geometry>
      <material
        name="">
        <color
          rgba="0.79216 0.81961 0.93333 1" />
      </material>
    </visual>
    <collision>
      <origin
        xyz="0 0 0"
        rpy="0 0 0" />
      <geometry>
        <mesh
          filename="package://RobotBimanualV4//collision/cvx_link5.obj" />
      </geometry>
    </collision>
  </link>
  <joint
    name="joint5"
    type="revolute">
    <origin
      xyz="0.014 0.00010349 0"
      rpy="-1.5708 0 -1.5708" />
    <parent
      link="link4" />
    <child
      link="link5" />
    <axis
      xyz="0 0 1" />
    <limit
      lower="-3.66519143"
      upper="3.66519143"
      effort="1"
      velocity="15.0" />
  </joint>
  <link
    name="link6">
    <inertial>
      <origin
        xyz="0.00013661 0.032632 -0.015041"
        rpy="0 0 0" />
      <mass
        value="0.10024" />
      <inertia
        ixx="3.6405E-05"
        ixy="2.2542E-07"
        ixz="-1.3425E-07"
        iyy="2.5551E-05"
        iyz="-4.2981E-07"
        izz="4.9498E-05" />
    </inertial>
    <visual>
      <origin
        xyz="0 0 0"
        rpy="0 0 0" />
      <geometry>
        <mesh
          filename="package://gripper_urdf/meshes/link6.STL" />
      </geometry>
      <material
        name="">
        <color
          rgba="0.79216 0.81961 0.93333 1" />
      </material>
    </visual>
    <collision>
      <origin
        xyz="0 0 0"
        rpy="0 0 0" />
      <geometry>
        <mesh
          filename="package://gripper_urdf/meshes/link6.STL" />
      </geometry>
    </collision>
  </link>
  <joint
    name="joint6"
    type="revolute">
    <origin
      xyz="0.012203 0 0.2634"
      rpy="1.5708 0 1.5708" />
    <parent
      link="link5" />
    <child
      link="link6" />
    <axis
      xyz="0 0 1" />
    <limit
      lower="-2.18166156"
      upper="2.18166156"
      effort="1"
      velocity="15.0" />
  </joint>
  <link
    name="link7">
    <inertial>
      <origin
        xyz="0.00239406 -0.00016204 0.05155291"
        rpy="0 0 0" />
      <mass
        value="0.706" />
      <inertia
        ixx="0.00074592"
        ixy="-2.03E-06"
        ixz="-1.52E-06"
        iyy="0.00053798"
        iyz="-3.35E-06"
        izz="0.00050821" />
    </inertial>
    <visual>
      <origin
        xyz="0 0 0"
        rpy="0 0 0" />
      <geometry>
        <mesh
          filename="package://RobotBimanualV4//visual/link7.obj" />
      </geometry>
      <material
        name="">
        <color
          rgba="0.79216 0.81961 0.93333 1" />
      </material>
    </visual>
    <collision>
      <origin
        xyz="0 0 0"
        rpy="0 0 0" />
      <geometry>
        <mesh
          filename="package://RobotBimanualV4//collision/cvx_link7.obj" />
      </geometry>
    </collision>
  </link>
  <joint
    name="joint7"
    type="revolute">
    <origin
      xyz="0.02 -0.1036 0.8358"
      rpy="0 0 0" />
    <parent
      link="base_link" />
    <child
      link="link7" />
    <axis
      xyz="0 0 1" />
    <limit
      lower="-0.87266463"
      upper="1.57079633"
      effort="4"
      velocity="10.00" />  
  </joint>
  <link
    name="link8">
    <inertial>
      <origin
        xyz="-0.00124394 7.606E-05 0.05454155"
        rpy="0 0 0" />
      <mass
        value="0.659" />
      <inertia
        ixx="0.00064811"
        ixy="-1.1E-06"
        ixz="-7.3E-07"
        iyy="0.0004522"
        iyz="1.03E-06"
        izz="0.00043369" />
    </inertial>
    <visual>
      <origin
        xyz="0 0 0"
        rpy="0 0 0" />
      <geometry>
        <mesh
          filename="package://RobotBimanualV4//visual/link8.obj" />
      </geometry>
      <material
        name="">
        <color
          rgba="0.79216 0.81961 0.93333 1" />
      </material>
    </visual>
    <collision>
      <origin
        xyz="0 0 0"
        rpy="0 0 0" />
      <geometry>
        <mesh
          filename="package://RobotBimanualV4//collision/cvx_link8.obj" />
      </geometry>
    </collision>
  </link>
  <joint
    name="joint8"
    type="revolute">
    <origin
      xyz="-0.02205 0 0.0528"
      rpy="1.5708 0 -1.5708" />
    <parent
      link="link7" />
    <child
      link="link8" />
    <axis
      xyz="0 0 1" />
    <limit
      lower="-1.3962634"
      upper="1.57079633"
      effort="4"
      velocity="10.00" />
  </joint>
  <link
    name="link9">
    <inertial>
      <origin
        xyz="-0.03505563 0.00468094 0.05453087"
        rpy="0 0 0" />
      <mass
        value="1.095" />
      <inertia
        ixx="0.00161845"
        ixy="-0.00039365"
        ixz="-0.00105521"
        iyy="0.00662637"
        iyz="0.00018923"
        izz="0.00652496" />
    </inertial>
    <visual>
      <origin
        xyz="0 0 0"
        rpy="0 0 0" />
      <geometry>
        <mesh
          filename="package://RobotBimanualV4//visual/link9.obj" />
      </geometry>
      <material
        name="">
        <color
          rgba="0.79216 0.81961 0.93333 1" />
      </material>
    </visual>
    <collision>
      <origin
        xyz="0 0 0"
        rpy="0 0 0" />
      <geometry>
        <mesh
          filename="package://RobotBimanualV4//collision/cvx_link9.obj" />
      </geometry>
    </collision>
  </link>
  <joint
    name="joint9"
    type="revolute">
    <origin
      xyz="0.023 0 0.0565"
      rpy="1.5708 0 1.5708" />
    <parent
      link="link8" />
    <child
      link="link9" />
    <axis
      xyz="0 0 1" />
    <limit
      lower="-1.3962634"
      upper="3.14159265"
      effort="4"
      velocity="10.00" />
  </joint>
  <link
    name="link10">
    <inertial>
      <origin
        xyz="-0.00914828 -0.00042727 7.13E-06"
        rpy="0 0 0" />
      <mass
        value="0.268" />
      <inertia
        ixx="9.136E-05"
        ixy="7E-08"
        ixz="2E-08"
        iyy="0.00013894"
        iyz="0"
        izz="0.00013031" />
    </inertial>
    <visual>
      <origin
        xyz="0 0 0"
        rpy="0 0 0" />
      <geometry>
        <mesh
          filename="package://RobotBimanualV4//visual/link10.obj" />
      </geometry>
      <material
        name="">
        <color
          rgba="0.79216 0.81961 0.93333 1" />
      </material>
    </visual>
    <collision>
      <origin
        xyz="0 0 0"
        rpy="0 0 0" />
      <geometry>
        <mesh
          filename="package://RobotBimanualV4//collision/cvx_link10.obj" />
      </geometry>
    </collision>
  </link>
  <joint
    name="joint10"
    type="revolute">
    <origin
      xyz="-0.25 0 0.08318"
      rpy="-3.1416 0 -1.5708" />
    <parent
      link="link9" />
    <child
      link="link10" />
    <axis
      xyz="0 0 1" />
    <limit
      lower="-1.30899694"
      upper="0.78539816"
      effort="4"
      velocity="10.00" />
  </joint>
  <link
    name="link11">
    <inertial>
      <origin
        xyz="-0.00143459 -5.019E-05 0.22261684"
        rpy="0 0 0" />
      <mass
        value="0.285" />
      <inertia
        ixx="0.00170458"
        ixy="1.5E-07"
        ixz="-2.111E-05"
        iyy="0.00168732"
        iyz="-5.6E-07"
        izz="7.029E-05" />
    </inertial>
    <visual>
      <origin
        xyz="0 0 0"
        rpy="0 0 0" />
      <geometry>
        <mesh
          filename="package://RobotBimanualV4//visual/link11.obj" />
      </geometry>
      <material
        name="">
        <color
          rgba="0.79216 0.81961 0.93333 1" />
      </material>
    </visual>
    <collision>
      <origin
        xyz="0 0 0"
        rpy="0 0 0" />
      <geometry>
        <mesh
          filename="package://RobotBimanualV4//collision/cvx_link11.obj" />
      </geometry>
    </collision>
  </link>
  <joint
    name="joint11"
    type="revolute">
    <origin
      xyz="0.014 0.00010349 0"
      rpy="-1.5708 0 -1.5708" />
    <parent
      link="link10" />
    <child
      link="link11" />
    <axis
      xyz="0 0 1" />
    <limit
      lower="-3.66519143"
      upper="1.91986218"
      effort="1"
      velocity="15.00" />
  </joint>
  <link
    name="link12">
    <inertial>
      <origin
        xyz="0.00013661 0.032632 -0.015041"
        rpy="0 0 0" />
      <mass
        value="0.10024" />
      <inertia
        ixx="3.6405E-05"
        ixy="2.2542E-07"
        ixz="-1.3425E-07"
        iyy="2.5551E-05"
        iyz="-4.2981E-07"
        izz="4.9498E-05" />
    </inertial>
    <visual>
      <origin
        xyz="0 0 0"
        rpy="0 0 0" />
      <geometry>
        <mesh
          filename="package://gripper_urdf/meshes/link6.STL" />
      </geometry>
      <material
        name="">
        <color
          rgba="0.79216 0.81961 0.93333 1" />
      </material>
    </visual>
    <collision>
      <origin
        xyz="0 0 0"
        rpy="0 0 0" />
      <geometry>
        <mesh
          filename="package://gripper_urdf/meshes/link6.STL" />
      </geometry>
    </collision>
  </link>
  <joint
    name="joint12"
    type="revolute">
    <origin
      xyz="0.012203 0 0.2634"
      rpy="1.5708 0 1.5708" />
    <parent
      link="link11" />
    <child
      link="link12" />
    <axis
      xyz="0 0 1" />
    <limit
      lower="-2.18166156"
      upper="2.18166156"
      effort="1"
      velocity="15.0" />
  </joint>

  <!-- hand attached to link 6 -->
  <link
    name="finger1_link">
    <inertial>
      <origin
        xyz="0.00715155519277111 0.0317897449447876 -0.022639994299902"
        rpy="0 0 0" />
      <mass
        value="0.0434439521158079" />
      <inertia
        ixx="1.61853165636498E-05"
        ixy="-8.29742557186773E-07"
        ixz="2.83702473101179E-08"
        iyy="7.96070872508349E-06"
        iyz="2.10305920009734E-07"
        izz="1.59719393438006E-05" />
    </inertial>
    <visual>
      <origin
        xyz="0 0 0"
        rpy="0 0 0" />
      <geometry>
        <mesh
          filename="package://gripper_urdf/meshes/finger1_link.obj" />
      </geometry>
      <material
        name="">
        <color
          rgba="0.792156862745098 0.819607843137255 0.933333333333333 1" />
      </material>
    </visual>
    <collision>
      <origin
        xyz="0 0 0"
        rpy="0 0 0" />
      <geometry>
        <mesh
          filename="package://gripper_urdf/cvx/7_coacd/finger1_link.obj" />
      </geometry>
    </collision>
  </link>
  <joint
    name="finger1_joint"
    type="revolute">
    <origin
      xyz="0.01225 0.046 0.009"
      rpy="0 0 0" />
    <parent
      link="link6" />
    <child
      link="finger1_link" />
    <axis
      xyz="0 0 1" />
    <limit
      lower="-1"
      upper="0"
      effort="0"
      velocity="0" />
  </joint>
  <link
    name="finger2_link">
    <inertial>
      <origin
        xyz="-0.0071525 0.031874 -0.022696"
        rpy="0 0 0" />
      <mass
        value="0.043258" />
      <inertia
        ixx="1.6034E-05"
        ixy="7.6046E-07"
        ixz="-9.2887E-09"
        iyy="7.9067E-06"
        iyz="1.7744E-07"
        izz="1.5799E-05" />
    </inertial>
    <visual>
      <origin
        xyz="0 0 0"
        rpy="0 0 0" />
      <geometry>
        <mesh
          filename="package://gripper_urdf/meshes/finger2_link.obj" />
      </geometry>
      <material
        name="">
        <color
          rgba="0.75686 0.76863 0.75294 1" />
      </material>
    </visual>
    <collision>
      <origin
        xyz="0 0 0"
        rpy="0 0 0" />
      <geometry>
        <mesh
          filename="package://gripper_urdf/cvx/7_coacd/finger2_link.obj" />
      </geometry>
    </collision>
  </link>
  <joint
    name="finger2_joint"
    type="revolute">
    <origin
      xyz="-0.01225 0.046 0.009"
      rpy="0 0 0" />
    <parent
      link="link6" />
    <child
      link="finger2_link" />
    <axis
      xyz="0 0 1" />
    <limit
      lower="0"
      upper="1"
      effort="0"
      velocity="0" />
  </joint>


  <!-- hand attached to link 12 -->
  <link
    name="finger3_link">
    <inertial>
      <origin
        xyz="0.00715155519277111 0.0317897449447876 -0.022639994299902"
        rpy="0 0 0" />
      <mass
        value="0.0434439521158079" />
      <inertia
        ixx="1.61853165636498E-05"
        ixy="-8.29742557186773E-07"
        ixz="2.83702473101179E-08"
        iyy="7.96070872508349E-06"
        iyz="2.10305920009734E-07"
        izz="1.59719393438006E-05" />
    </inertial>
    <visual>
      <origin
        xyz="0 0 0"
        rpy="0 0 0" />
      <geometry>
        <mesh
          filename="package://gripper_urdf/meshes/finger1_link.obj" />
      </geometry>
      <material
        name="">
        <color
          rgba="0.792156862745098 0.819607843137255 0.933333333333333 1" />
      </material>
    </visual>
    <collision>
      <origin
        xyz="0 0 0"
        rpy="0 0 0" />
      <geometry>
        <mesh
          filename="package://gripper_urdf/cvx/7_coacd/finger1_link.obj" />
      </geometry>
    </collision>
  </link>
  <joint
    name="finger3_joint"
    type="revolute">
    <origin
      xyz="0.01225 0.046 0.009"
      rpy="0 0 0" />
    <parent
      link="link12" />
    <child
      link="finger3_link" />
    <axis
      xyz="0 0 1" />
    <limit
      lower="-1"
      upper="0"
      effort="0"
      velocity="0" />
  </joint>
  <link
    name="finger4_link">
    <inertial>
      <origin
        xyz="-0.0071525 0.031874 -0.022696"
        rpy="0 0 0" />
      <mass
        value="0.043258" />
      <inertia
        ixx="1.6034E-05"
        ixy="7.6046E-07"
        ixz="-9.2887E-09"
        iyy="7.9067E-06"
        iyz="1.7744E-07"
        izz="1.5799E-05" />
    </inertial>
    <visual>
      <origin
        xyz="0 0 0"
        rpy="0 0 0" />
      <geometry>
        <mesh
          filename="package://gripper_urdf/meshes/finger2_link.obj" />
      </geometry>
      <material
        name="">
        <color
          rgba="0.75686 0.76863 0.75294 1" />
      </material>
    </visual>
    <collision>
      <origin
        xyz="0 0 0"
        rpy="0 0 0" />
      <geometry>
        <mesh
          filename="package://gripper_urdf/cvx/7_coacd/finger2_link.obj" />
      </geometry>
    </collision>
  </link>
  <joint
    name="finger4_joint"
    type="revolute">
    <origin
      xyz="-0.01225 0.046 0.009"
      rpy="0 0 0" />
    <parent
      link="link12" />
    <child
      link="finger4_link" />
    <axis
      xyz="0 0 1" />
    <limit
      lower="0"
      upper="1"
      effort="0"
      velocity="0" />
  </joint>
  <link name="left_tool"/>
  <joint name="left_tool_joint" type="fixed">
    <parent link="link6"/>
    <child link="left_tool"/>
    <origin xyz="0 0.125 -0.015" rpy="0 0 0"/>
  </joint>
  <link name="right_tool"/>
  <joint name="right_tool_joint" type="fixed">
    <parent link="link12"/>
    <child link="right_tool"/>
    <origin xyz="0 0.125 -0.015" rpy="0 0 0"/>
  </joint>
</robot>